Workbook

Sheet Nhập kho  입2
D1: =SUM(D5:D266) -> 45720 | E1: 7
A2: ERP Code | B2: 모델명 Model | C2: TỒN ĐẦU KỲ | D2: TT In WH | F2: =SUM(F5:F274) -> 0 | G2: =SUM(G5:G274) -> 0 | H2: =SUM(H5:H274) -> 0 | I2: =SUM(I5:I274) -> 0 | J2: =SUM(J5:J274) -> 28040 | K2: =SUM(K5:K274) -> 0 | L2: =SUM(L5:L274) -> 25480 | M2: =SUM(M5:M274) -> 0 | ... BN2: =SUM(BN5:BN274) -> 0
E3: =DATE(2026,$E$1,1) -> 46204 | G3: =+E3+1 -> 46205 | I3: =+G3+1 -> 46206 | K3: =+I3+1 -> 46207 | M3: =+K3+1 -> 46208 | O3: =+M3+1 -> 46209 | Q3: =+O3+1 -> 46210 | S3: =+Q3+1 -> 46211 | U3: =+S3+1 -> 46212 | W3: =+U3+1 -> 46213 | Y3: =+W3+1 -> 46214 | AA3: =+Y3+1 -> 46215 | AC3: =+AA3+1 -> 46216 | AE3: =+AC3+1 -> 46217 | AG3: =+AE3+1 -> 46218 | AI3: =+AG3+1 -> 46219 | AK3: =+AI3+1 -> 46220 | AM3: =+AK3+1 -> 46221 | AO3: =+AM3+1 -> 46222 | AQ3: =+AO3+1 -> 46223 | AS3: =+AQ3+1 -> 46224 | AU3: =+AS3+1 -> 46225 | AW3: =+AU3+1 -> 46226 | AY3: =+AW3+1 -> 46227 | BA3: =+AY3+1 -> 46228 | BC3: =+BA3+1 -> 46229 | BE3: =+BC3+1 -> 46230 | BG3: =+BE3+1 -> 46231 | BI3: =+BG3+1 -> 46232 | BK3: =+BI3+1 -> 46233 | BM3: =+BK3+1 -> 46234 | BO3: TT Produc
E4: Produc | F4: wh | G4: Produc | H4: wh | I4: Produc | J4: wh | K4: Produc | L4: wh | M4: Produc | N4: wh | O4: Produc | P4: wh | Q4: Produc | R4: wh | S4: Produc | T4: wh | U4: Produc | V4: wh | W4: Produc | X4: wh | Y4: Produc | Z4: wh | AA4: Produc | AB4: wh | AC4: Produc | AD4: wh | AE4: Produc | AF4: wh | AG4: Produc | AH4: wh | AI4: Produc | AJ4: wh | AK4: Produc | AL4: wh | AM4: Produc | AN4: wh | AO4: Produc | AP4: wh | AQ4: Produc | AR4: wh | AS4: Produc | AT4: wh | AU4: Produc | AV4: wh | AW4: Produc | AX4: wh | AY4: Produc | AZ4: wh | BA4: Produc | BB4: wh | BC4: Produc | BD4: wh | BE4: Produc | BF4: wh | BG4: Produc | BH4: wh | BI4: Produc | BJ4: wh | BK4: Produc | BL4: wh | BM4: Produc | BN4: wh
A5: TR354631 | B5: KS-880854 | D5: =SUMIF($E$4:BN$4,$F$4,E5:BN5) -> 0 | BO5: =SUMIF(E4:$BN$4,$E$4,E5:BN5) -> 0 | BP5: =+VLOOKUP(A5,'Tổng,SUMMARY'!C:K,8,0) -> 1300 | BQ5: =+D5-BP5 -> -1300
A6: TR355517 | B6: KS-870953 | D6: =SUMIF($E$4:BN$4,$F$4,E6:BN6) -> 0 | BO6: =SUMIF(E$4:$BN5,$E$4,E6:BN6) -> 0 | BP6: =+VLOOKUP(A6,'Tổng,SUMMARY'!C:K,8,0) -> 950 | BQ6: =+D6-BP6 -> -950
A7: TR352805 | B7: KS-86025 | D7: =SUMIF($E$4:BN$4,$F$4,E7:BN7) -> 0 | BO7: =SUMIF(E$4:$BN6,$E$4,E7:BN7) -> 0 | BP7: =+VLOOKUP(A7,'Tổng,SUMMARY'!C:K,8,0) -> 1500 | BQ7: =+D7-BP7 -> -1500
A8: TR355201 | B8: KS-881058 | D8: =SUMIF($E$4:BN$4,$F$4,E8:BN8) -> 0 | BO8: =SUMIF(E$4:$BN7,$E$4,E8:BN8) -> 0 | BP8: =+VLOOKUP(A8,'Tổng,SUMMARY'!C:K,8,0) -> 1800 | BQ8: =+D8-BP8 -> -1800
A9: TR355324 | B9: KS-881058 | D9: =SUMIF($E$4:BN$4,$F$4,E9:BN9) -> 0 | BO9: =SUMIF(E$4:$BN8,$E$4,E9:BN9) -> 0 | BP9: =+VLOOKUP(A9,'Tổng,SUMMARY'!C:K,8,0) -> 0 | BQ9: =+D9-BP9 -> 0
A10: TR356580 | B10: KS-881515 | D10: =SUMIF($E$4:BN$4,$F$4,E10:BN10) -> 0 | BO10: =SUMIF(E$4:$BN9,$E$4,E10:BN10) -> 0 | BP10: =+VLOOKUP(A10,'Tổng,SUMMARY'!C:K,8,0) -> 850 | BQ10: =+D10-BP10 -> -850
A11: TR354796 | B11: KS-880355 | D11: =SUMIF($E$4:BN$4,$F$4,E11:BN11) -> 0 | BO11: =SUMIF(E$4:$BN10,$E$4,E11:BN11) -> 0 | BP11: =+VLOOKUP(A11,'Tổng,SUMMARY'!C:K,8,0) -> 400 | BQ11: =+D11-BP11 -> -400
A12: TR352133 | B12: KS-880355 | D12: =SUMIF($E$4:BN$4,$F$4,E12:BN12) -> 0 | BO12: =SUMIF(E$4:$BN11,$E$4,E12:BN12) -> 0 | BP12: =+VLOOKUP(A12,'Tổng,SUMMARY'!C:K,8,0) -> 0 | BQ12: =+D12-BP12 -> 0
A13: TR355056 | B13: KS-870827 | D13: =SUMIF($E$4:BN$4,$F$4,E13:BN13) -> 0 | BO13: =SUMIF(E$4:$BN12,$E$4,E13:BN13) -> 0 | BP13: =+VLOOKUP(A13,'Tổng,SUMMARY'!C:K,8,0) -> 300 | BQ13: =+D13-BP13 -> -300
A14: TR355708 | B14: KS-880827 | D14: =SUMIF($E$4:BN$4,$F$4,E14:BN14) -> 0 | BO14: =SUMIF(E$4:$BN13,$E$4,E14:BN14) -> 0 | BP14: =+VLOOKUP(A14,'Tổng,SUMMARY'!C:K,8,0) -> 50 | BQ14: =+D14-BP14 -> -50
A15: TR354801 | B15: KS-880545 | D15: =SUMIF($E$4:BN$4,$F$4,E15:BN15) -> 0 | BO15: =SUMIF(E$4:$BN14,$E$4,E15:BN15) -> 0 | BP15: =+VLOOKUP(A15,'Tổng,SUMMARY'!C:K,8,0) -> 0 | BQ15: =+D15-BP15 -> 0
A16: TR353236 | B16: KS-880545 | D16: =SUMIF($E$4:BN$4,$F$4,E16:BN16) -> 0 | BO16: =SUMIF(E$4:$BN15,$E$4,E16:BN16) -> 0 | BP16: =+VLOOKUP(A16,'Tổng,SUMMARY'!C:K,8,0) -> 0 | BQ16: =+D16-BP16 -> 0
A17: TR353611 | B17: KS-880616 | D17: =SUMIF($E$4:BN$4,$F$4,E17:BN17) -> 0 | BO17: =SUMIF(E$4:$BN16,$E$4,E17:BN17) -> 0 | BP17: =+VLOOKUP(A17,'Tổng,SUMMARY'!C:K,8,0) -> 200 | BQ17: =+D17-BP17 -> -200
... A19: TR354840 | B19: KS-89045 | D19: =SUMIF($E$4:BN$4,$F$4,E19:BN19) -> 0 | BO19: =SUMIF(E$4:$BN18,$E$4,E19:BN19) -> 0 | BP19: =+VLOOKUP(A19,'Tổng,SUMMARY'!C:K,8,0) -> 0 | BQ19: =+D19-BP19 -> 0
A20: TR355240 | B20: KS-89045 | D20: =SUMIF($E$4:BN$4,$F$4,E20:BN20) -> 0
A21: TR353452 | B21: KS-89045 | D21: =SUMIF($E$4:BN$4,$F$4,E21:BN21) -> 0 | BO21: =SUMIF(E$4:$BN19,$E$4,E21:BN21) -> 0 | BP21: =+VLOOKUP(A21,'Tổng,SUMMARY'!C:K,8,0) -> #N/A | BQ21: =+D21-BP21 -> #N/A
A22: TR354300 | B22: KS-880754 | D22: =SUMIF($E$4:BN$4,$F$4,E22:BN22) -> 0 | BO22: =SUMIF(E$4:$BN21,$E$4,E22:BN22) -> 0 | BP22: =+VLOOKUP(A22,'Tổng,SUMMARY'!C:K,8,0) -> 0 | BQ22: =+D22-BP22 -> 0
A23: TR354812 | B23: KS-880793 | D23: =SUMIF($E$4:BN$4,$F$4,E23:BN23) -> 0 | BO23: =SUMIF(E$4:$BN22,$E$4,E23:BN23) -> 0 | BP23: =+VLOOKUP(A23,'Tổng,SUMMARY'!C:K,8,0) -> 100 | BQ23: =+D23-BP23 -> -100
A24: TR354467 | B24: KS-880793 | D24: =SUMIF($E$4:BN$4,$F$4,E24:BN24) -> 0 | BO24: =SUMIF(E$4:$BN23,$E$4,E24:BN24) -> 0 | BP24: =+VLOOKUP(A24,'Tổng,SUMMARY'!C:K,8,0) -> 0 | BQ24: =+D24-BP24 -> 0
A25: TR352138 | B25: KS-874157 | D25: =SUMIF($E$4:BN$4,$F$4,E25:BN25) -> 0 | BO25: =SUMIF(E$4:$BN24,$E$4,E25:BN25) -> 0 | BP25: =+VLOOKUP(A25,'Tổng,SUMMARY'!C:K,8,0) -> 0 | BQ25: =+D25-BP25 -> 0
A26: TR351474 | B26: KS-874157 | D26: =SUMIF($E$4:BN$4,$F$4,E26:BN26) -> 0 | BO26: =SUMIF(E$4:$BN25,$E$4,E26:BN26) -> 0 | BP26: =+VLOOKUP(A26,'Tổng,SUMMARY'!C:K,8,0) -> 650 | BQ26: =+D26-BP26 -> -650
A27: TR354395 | B27: KS-880760 | D27: =SUMIF($E$4:BN$4,$F$4,E27:BN27) -> 0 | BO27: =SUMIF(E$4:$BN26,$E$4,E27:BN27) -> 0 | BP27: =+VLOOKUP(A27,'Tổng,SUMMARY'!C:K,8,0) -> 2500 | BQ27: =+D27-BP27 -> -2500
A28: TR352974 | B28: KS-8605 | D28: =SUMIF($E$4:BN$4,$F$4,E28:BN28) -> 0 | L28: =3600+(-3600) -> 0 | BO28: =SUMIF(E$4:$BN27,$E$4,E28:BN28) -> 0 | BP28: =+VLOOKUP(A28,'Tổng,SUMMARY'!C:K,8,0) -> 750 | BQ28: =+D28-BP28 -> -750
A29: TR350031 | B29: KS-8605 | D29: =SUMIF($E$4:BN$4,$F$4,E29:BN29) -> 0 | BO29: =SUMIF(E$4:$BN28,$E$4,E29:BN29) -> 0 | BP29: =+VLOOKUP(A29,'Tổng,SUMMARY'!C:K,8,0) -> 1750 | BQ29: =+D29-BP29 -> -1750
A30: TR352561 | B30: KS-8303 | D30: =SUMIF($E$4:BN$4,$F$4,E30:BN30) -> 0 | BO30: =SUMIF(E$4:$BN29,$E$4,E30:BN30) -> 0 | BP30: =+VLOOKUP(A30,'Tổng,SUMMARY'!C:K,8,0) -> 0 | BQ30: =+D30-BP30 -> 0
A31: TR300016 | B31: KS-8303 | D31: =SUMIF($E$4:BN$4,$F$4,E31:BN31) -> 0 | BO31: =SUMIF(E$4:$BN30,$E$4,E31:BN31) -> 0 | BP31: =+VLOOKUP(A31,'Tổng,SUMMARY'!C:K,8,0) -> 0 | BQ31: =+D31-BP31 -> 0
A32: TR353886 | B32: KS-870505 | D32: =SUMIF($E$4:BN$4,$F$4,E32:BN32) -> 0 | BO32: =SUMIF(E$4:$BN31,$E$4,E32:BN32) -> 0 | BP32: =+VLOOKUP(A32,'Tổng,SUMMARY'!C:K,8,0) -> 0 | BQ32: =+D32-BP32 -> 0
A33: TR355016 | B33: KS-881003 | D33: =SUMIF($E$4:BN$4,$F$4,E33:BN33) -> 0 | BO33: =SUMIF(E$4:$BN32,$E$4,E33:BN33) -> 0 | BP33: =+VLOOKUP(A33,'Tổng,SUMMARY'!C:K,8,0) -> 0 | BQ33: =+D33-BP33 -> 0
A34: TR354996 | B34: KS-880995 | D34: =SUMIF($E$4:BN$4,$F$4,E34:BN34) -> 0 | BO34: =SUMIF(E$4:$BN33,$E$4,E34:BN34) -> 0 | BP34: =+VLOOKUP(A34,'Tổng,SUMMARY'!C:K,8,0) -> 0 | BQ34: =+D34-BP34 -> 0
A35: TR353788 | B35: KS-870501 | D35: =SUMIF($E$4:BN$4,$F$4,E35:BN35) -> 0 | BO35: =SUMIF(E$4:$BN34,$E$4,E35:BN35) -> 0 | BP35: =+VLOOKUP(A35,'Tổng,SUMMARY'!C:K,8,0) -> 0 | BQ35: =+D35-BP35 -> 0
A36: TR353823 | B36: KS-870499 | D36: =SUMIF($E$4:BN$4,$F$4,E36:BN36) -> 0 | BO36: =SUMIF(E$4:$BN35,$E$4,E36:BN36) -> 0 | BP36: =+VLOOKUP(A36,'Tổng,SUMMARY'!C:K,8,0) -> 800 | BQ36: =+D36-BP36 -> -800
A37: TR354615 | B37: KS-870702 | D37: =SUMIF($E$4:BN$4,$F$4,E37:BN37) -> 0 | BO37: =SUMIF(E$4:$BN36,$E$4,E37:BN37) -> 0 | BP37: =+VLOOKUP(A37,'Tổng,SUMMARY'!C:K,8,0) -> 0 | BQ37: =+D37-BP37 -> 0
A38: TR354576 | B38: KS-870574 | D38: =SUMIF($E$4:BN$4,$F$4,E38:BN38) -> 0 | BO38: =SUMIF(E$4:$BN37,$E$4,E38:BN38) -> 0 | BP38: =+VLOOKUP(A38,'Tổng,SUMMARY'!C:K,8,0) -> 1400 | BQ38: =+D38-BP38 -> -1400
A39: TR350607 | B39: KS-84018 | D39: =SUMIF($E$4:BN$4,$F$4,E39:BN39) -> 0 | BO39: =SUMIF(E$4:$BN38,$E$4,E39:BN39) -> 0 | BP39: =+VLOOKUP(A39,'Tổng,SUMMARY'!C:K,8,0) -> 1100 | BQ39: =+D39-BP39 -> -1100
A40: TR357034 | B40: KS-881291 | D40: =SUMIF($E$4:BN$4,$F$4,E40:BN40) -> 0 | BO40: =SUMIF(E$4:$BN39,$E$4,E40:BN40) -> 0 | BP40: =+VLOOKUP(A40,'Tổng,SUMMARY'!C:K,8,0) -> 250 | BQ40: =+D40-BP40 -> -250
A41: TR355877 | B41: KS-881291 | D41: =SUMIF($E$4:BN$4,$F$4,E41:BN41) -> 0
...

Sheet  Xuất kho 출2
A1: 월 출고 XUẤT HÀNG | D1: =SUM(E1:AI1) -> 28400 | E1: =+E274 -> 0 | F1: =+F274 -> 0 | G1: =+G274 -> 8000 | H1: =+H274 -> 20400 | I1: =+I274 -> 0 | J1: =+J274 -> 0 | K1: =+K274 -> 0 | L1: =+L274 -> 0 | ... AI1: =+AI274 -> 0
B2: ERP Code | C2: 모델명 Model | D2: TT XUẤT | S2: DATE
E3: 1 | F3: =+E3+1 -> 2 | G3: =+F3+1 -> 3 | H3: =+G3+1 -> 4 | I3: =+H3+1 -> 5 | J3: =+I3+1 -> 6 | K3: =+J3+1 -> 7 | L3: =+K3+1 -> 8 | M3: =+L3+1 -> 9 | ... AI3: =+AH3+1 -> 31 | XFB3: =SUM(A3:XFA3) -> 496
B4: TR354631 | C4: KS-880854 | D4: =SUM(E4:AI4) -> 0 | AK4: =+D4-AJ4 -> 0
B5: TR355517 | C5: KS-870953 | D5: =SUM(E5:AI5) -> 0 | AK5: =+D5-AJ5 -> 0
B6: TR352805 | C6: KS-86025 | D6: =SUM(E6:AI6) -> 0 | AK6: =+D6-AJ6 -> 0
B7: TR355201 | C7: KS-881058 | D7: =SUM(E7:AI7) -> 0 | AK7: =+D7-AJ7 -> 0
B8: TR355324 | C8: KS-881058 | D8: =SUM(E8:AI8) -> 0 | AK8: =+D8-AJ8 -> 0
B9: TR356580 | C9: KS-881515 | D9: =SUM(E9:AI9) -> 0 | AK9: =+D9-AJ9 -> 0
B10: TR354796 | C10: KS-880355 | D10: =SUM(E10:AI10) -> 0 | AK10: =+D10-AJ10 -> 0
B11: TR352133 | C11: KS-880355 | D11: =SUM(E11:AI11) -> 0 | AK11: =+D11-AJ11 -> 0
B12: TR355056 | C12: KS-870827 | D12: =SUM(E12:AI12) -> 0 | AK12: =+D12-AJ12 -> 0
B13: TR355708 | C13: KS-880827 | D13: =SUM(E13:AI13) -> 0 | AK13: =+D13-AJ13 -> 0
B14: TR354801 | C14: KS-880545 | D14: =SUM(E14:AI14) -> 0 | AK14: =+D14-AJ14 -> 0
B15: TR353236 | C15: KS-880545 | D15: =SUM(E15:AI15) -> 0 | AK15: =+D15-AJ15 -> 0
... B38: TR357034 | C38: KS-881291 | D38: =SUM(E38:AI38) -> 0 | AK38: =+D38-AJ38 -> 0
B39: TR355877 | C39: KS-881291 | D39: =SUM(E39:AI39) -> 0
B40: TR355278 | C40: KS-870883 | D40: =SUM(E40:AI40) -> 0 | AK40: =+D40-AJ40 -> 0
B41: TR351752 | C41: KS-880288 | D41: =SUM(E41:AI41) -> 0 | AK41: =+D41-AJ41 -> 0
B42: TR356497 | C42: KS-881512 | D42: =SUM(E42:AI42) -> 0 | AK42: =+D42-AJ42 -> 0
B43: TR354759 | C43: KS-880910 | D43: =SUM(E43:AI43) -> 0 | AK43: =+D43-AJ43 -> 0
B44: TR354920 | C44: KS-880910 | D44: =SUM(E44:AI44) -> 0 | AK44: =+D44-AJ44 -> 0
B45: TR355940 | C45: KS-881169 | D45: =SUM(E45:AI45) -> 8000 | G45: 8000 | AK45: =+D45-AJ45 -> 8000
B46: TR356242 | C46: KS-881169 | D46: =SUM(E46:AI46) -> 0 | AK46: =+D46-AJ46 -> 0
B47: TR353094 | C47: KS-880510 | D47: =SUM(E47:AI47) -> 0 | AK47: =+D47-AJ47 -> 0
B48: TR354914 | C48: KS-880959 | D48: =SUM(E48:AI48) -> 10000 | H48: 10000 | AK48: =+D48-AJ48 -> 10000
B49: TR355573 | C49: KS-870990 | D49: =SUM(E49:AI49) -> 0 | AK49: =+D49-AJ49 -> 0
B50: TR351690 | C50: KS-880272 | D50: =SUM(E50:AI50) -> 0 | AK50: =+D50-AJ50 -> 0
B51: TR354011 | C51: KS-880624 | D51: =SUM(E51:AI51) -> 0 | AK51: =+D51-AJ51 -> 0
B52: TR354102 | C52: KS-880624 | D52: =SUM(E52:AI52) -> 0 | AK52: =+D52-AJ52 -> 0
B53: TR354763 | C53: KS-880898 | D53: =SUM(E53:AI53) -> 0 | AK53: =+D53-AJ53 -> 0
B54: TR352576 | C54: KS-880398 | D54: =SUM(E54:AI54) -> 0 | AK54: =+D54-AJ54 -> 0
B55: TR353653 | C55: KS-880615 | D55: =SUM(E55:AI55) -> 0 | AK55: =+D55-AJ55 -> 0
B56: TR352235 | C56: KS-88188 | D56: =SUM(E56:AI56) -> 0 | AK56: =+D56-AJ56 -> 0
B57: TR350693 | C57: KS-88188 | D57: =SUM(E57:AI57) -> 0 | AK57: =+D57-AJ57 -> 0
B58: TR354410 | C58: KS-880551 | D58: =SUM(E58:AI58) -> 0 | AK58: =+D58-AJ58 -> 0
B59: TR354542 | C59: KS-880551 | D59: =SUM(E59:AI59) -> 0 | AK59: =+D59-AJ59 -> 0
B60: TR353099 | C60: KS-880506 | D60: =SUM(E60:AI60) -> 0 | AK60: =+D60-AJ60 -> 0
... B114: TR355160 | C114: KS-881043 | D114: =SUM(E114:AI114) -> 0 | AK114: =+D114-AJ114 -> 0
B115: TR354773 | C115: KS-880120 | D115: =SUM(E115:AI115) -> 400 | H115: 400 | AK115: =+D115-AJ115 -> 400
...

Sheet Nhập kho  입
A2: (INPUT)
A4: CODE | B4: DESCRIPTION | C4: DATE | D4: Lot No | E4: Qty | F4: Remark
E5: =+SUBTOTAL(9,E6:E911) -> 614022
A6: TR355876 | B6: =IFERROR(VLOOKUP(A6,'Tổng,SUMMARY'!C:D,2,0),) -> KS-880104 | C6: 46296 | E6: 1200
A7: TR355199 | B7: =IFERROR(VLOOKUP(A7,'Tổng,SUMMARY'!C:D,2,0),) -> KS-881047 | C7: 46296 | E7: 1200
A8: TR356716 | B8: =IFERROR(VLOOKUP(A8,'Tổng,SUMMARY'!C:D,2,0),) -> KS-880975 | C8: 46296 | E8: =400+1000 -> 1400
A9: TR354809 | B9: =IFERROR(VLOOKUP(A9,'Tổng,SUMMARY'!C:D,2,0),) -> KS-880748 | C9: 46296 | E9: =1200+1200+900 -> 3300
A10: TR355918 | B10: =IFERROR(VLOOKUP(A10,'Tổng,SUMMARY'!C:D,2,0),) -> KS-881300 | C10: 46296 | E10: 3600
A11: TR356300 | B11: =IFERROR(VLOOKUP(A11,'Tổng,SUMMARY'!C:D,2,0),) -> KS-881462 | C11: 46296 | E11: 2300
A12: TR356346 | B12: =IFERROR(VLOOKUP(A12,'Tổng,SUMMARY'!C:D,2,0),) -> KS-881362 | C12: 46296 | E12: 2400
A13: TR352431 | B13: =IFERROR(VLOOKUP(A13,'Tổng,SUMMARY'!C:D,2,0),) -> KS-880374 | C13: 46296 | E13: 2400
A14: TR355366 | B14: =IFERROR(VLOOKUP(A14,'Tổng,SUMMARY'!C:D,2,0),) -> KS-89046 | C14: 46296 | E14: =750+780+780+780+300 -> 3390
A15: TR350693 | B15: =IFERROR(VLOOKUP(A15,'Tổng,SUMMARY'!C:D,2,0),) -> KS-88188 | C15: 46296 | E15: =500+1200+1200+1200+1000 -> 5100
A16: TR354914 | B16: =IFERROR(VLOOKUP(A16,'Tổng,SUMMARY'!C:D,2,0),) -> KS-880959 | C16: 46296 | E16: =2400+2400 -> 4800 | F16: hàng hyun
A17: TR354288 | B17: =IFERROR(VLOOKUP(A17,'Tổng,SUMMARY'!C:D,2,0),) -> KS-880753 | C17: 46296 | E17: 3600 | F17: hàng hyun
A18: TR350031 | B18: =IFERROR(VLOOKUP(A18,'Tổng,SUMMARY'!C:D,2,0),) -> KS-8605 | C18: 46296 | E18: 3600 | F18: hàng hyun
A19: TR354952 | B19: =IFERROR(VLOOKUP(A19,'Tổng,SUMMARY'!C:D,2,0),) -> KS-880944 | C19: 46296 | E19: 3600 | F19: hàng hyun
A20: TR356497 | B20: =IFERROR(VLOOKUP(A20,'Tổng,SUMMARY'!C:D,2,0),) -> KS-881512 | C20: 46296 | E20: 3600 | F20: hàng hyun
A21: TR352431 | B21: =IFERROR(VLOOKUP(A21,'Tổng,SUMMARY'!C:D,2,0),) -> KS-880374 | C21: 46297 | E21: 1200
A22: TR356346 | B22: =IFERROR(VLOOKUP(A22,'Tổng,SUMMARY'!C:D,2,0),) -> KS-881362 | C22: 46297 | E22: 1150
A23: TR353125 | B23: =IFERROR(VLOOKUP(A23,'Tổng,SUMMARY'!C:D,2,0),) -> KS-8809 | C23: 46297 | E23: 3600
A24: TR355876 | B24: =IFERROR(VLOOKUP(A24,'Tổng,SUMMARY'!C:D,2,0),) -> KS-880104 | C24: 46297 | E24: =1200+200+1150 -> 2550
A25: TR355918 | B25: =IFERROR(VLOOKUP(A25,'Tổng,SUMMARY'!C:D,2,0),) -> KS-881300 | C25: 46297 | E25: =1100+1200+1100+1200 -> 4600
A26: TR356505 | B26: =IFERROR(VLOOKUP(A26,'Tổng,SUMMARY'!C:D,2,0),) -> KS-881527 | C26: 46297 | E26: 3600
A27: TR356061 | B27: =IFERROR(VLOOKUP(A27,'Tổng,SUMMARY'!C:D,2,0),) -> KS-871270 | C27: 46297 | E27: 2400
A28: TR355136 | B28: =IFERROR(VLOOKUP(A28,'Tổng,SUMMARY'!C:D,2,0),) -> KS-881041 | C28: 46297 | E28: =3600+800+600 -> 5000
A29: TR355208 | B29: =IFERROR(VLOOKUP(A29,'Tổng,SUMMARY'!C:D,2,0),) -> KS-881057 | C29: 46297 | E29: 4800
A30: TR354288 | B30: =IFERROR(VLOOKUP(A30,'Tổng,SUMMARY'!C:D,2,0),) -> KS-880753 | C30: 46297 | E30: 3600 | F30: hàng hyun
A31: TR354952 | B31: =IFERROR(VLOOKUP(A31,'Tổng,SUMMARY'!C:D,2,0),) -> KS-880944 | C31: 46297 | E31: 3600 | F31: hàng hyun
A32: TR352561 | B32: =IFERROR(VLOOKUP(A32,'Tổng,SUMMARY'!C:D,2,0),) -> KS-8303 | C32: 46297 | E32: 3600 | F32: hàng hyun
A33: TR350031 | B33: =IFERROR(VLOOKUP(A33,'Tổng,SUMMARY'!C:D,2,0),) -> KS-8605 | C33: 46297 | E33: -3600 | F33: hàng hyun
A34: TR356061 | B34: =IFERROR(VLOOKUP(A34,'Tổng,SUMMARY'!C:D,2,0),) -> KS-871270 | C34: 46298 | E34: 850
A35: TR356346 | B35: =IFERROR(VLOOKUP(A35,'Tổng,SUMMARY'!C:D,2,0),) -> KS-881362 | C35: 46298 | E35: 1200
A36: TR355136 | B36: =IFERROR(VLOOKUP(A36,'Tổng,SUMMARY'!C:D,2,0),) -> KS-881041 | C36: 46298 | E36: =100+1200 -> 1300
A37: TR354952 | B37: =IFERROR(VLOOKUP(A37,'Tổng,SUMMARY'!C:D,2,0),) -> KS-880944 | C37: 46298 | E37: 1000
A38: TR353125 | B38: =IFERROR(VLOOKUP(A38,'Tổng,SUMMARY'!C:D,2,0),) -> KS-8809 | C38: 46298 | E38: 1200
A39: TR355199 | B39: =IFERROR(VLOOKUP(A39,'Tổng,SUMMARY'!C:D,2,0),) -> KS-881047 | C39: 46298 | E39: 1200
A40: TR356620 | B40: =IFERROR(VLOOKUP(A40,'Tổng,SUMMARY'!C:D,2,0),) -> KS-890195 | C40: 46298 | E40: =780+780+780 -> 2340
A41: TR355208 | B41: =IFERROR(VLOOKUP(A41,'Tổng,SUMMARY'!C:D,2,0),) -> KS-881057 | C41: 46298 | E41: =700+6000 -> 6700
A42: TR356300 | B42: =IFERROR(VLOOKUP(A42,'Tổng,SUMMARY'!C:D,2,0),) -> KS-881462 | C42: 46298 | E42: =2200+1000 -> 3200
...

Sheet  Xuất kho 출
A2: (OUTPUT)
A4: CODE | B4: DESCRIPTION | C4: DATE | D4: Lot No | E4: Qty | F4: Remark
E5: =+SUBTOTAL(9,E6:E893) -> 492610
A6: TR355713 | B6: =IFERROR(VLOOKUP(A6,'Tổng,SUMMARY'!C:D,2,0),) -> KS-870270 | C6: 46296 | E6: 1200
A7: TR352536 | B7: =IFERROR(VLOOKUP(A7,'Tổng,SUMMARY'!C:D,2,0),) -> KS-870317 | C7: 46296 | E7: 500
A8: TR351833 | B8: =IFERROR(VLOOKUP(A8,'Tổng,SUMMARY'!C:D,2,0),) -> KS-870253 | C8: 46296 | E8: 500
A9: TR356716 | B9: =IFERROR(VLOOKUP(A9,'Tổng,SUMMARY'!C:D,2,0),) -> KS-880975 | C9: 46296 | E9: 900
A10: TR352558 | B10: =IFERROR(VLOOKUP(A10,'Tổng,SUMMARY'!C:D,2,0),) -> KS-880373 | C10: 46297 | E10: 400
A11: TR355918 | B11: =IFERROR(VLOOKUP(A11,'Tổng,SUMMARY'!C:D,2,0),) -> KS-881300 | C11: 46297 | E11: =2000+2000 -> 4000
A12: TR354738 | B12: =IFERROR(VLOOKUP(A12,'Tổng,SUMMARY'!C:D,2,0),) -> KS-880575 | C12: 46297 | E12: 1000
A13: TR355876 | B13: =IFERROR(VLOOKUP(A13,'Tổng,SUMMARY'!C:D,2,0),) -> KS-880104 | C13: 46297 | E13: 2000
A14: TR356061 | B14: =IFERROR(VLOOKUP(A14,'Tổng,SUMMARY'!C:D,2,0),) -> KS-871270 | C14: 46297 | E14: 1000
A15: TR354914 | B15: =IFERROR(VLOOKUP(A15,'Tổng,SUMMARY'!C:D,2,0),) -> KS-880959 | C15: 46297 | E15: 10000
A16: TR352327 | B16: =IFERROR(VLOOKUP(A16,'Tổng,SUMMARY'!C:D,2,0),) -> KS-880372 | C16: 46297 | E16: 10000
A17: TR355918 | B17: =IFERROR(VLOOKUP(A17,'Tổng,SUMMARY'!C:D,2,0),) -> KS-881300 | C17: 46297 | E17: 2000
A18: TR352059 | B18: =IFERROR(VLOOKUP(A18,'Tổng,SUMMARY'!C:D,2,0),) -> KS-880351 | C18: 46297 | E18: 800
A19: TR355208 | B19: =IFERROR(VLOOKUP(A19,'Tổng,SUMMARY'!C:D,2,0),) -> KS-881057 | C19: 46297 | E19: 2400
A20: TR355199 | B20: =IFERROR(VLOOKUP(A20,'Tổng,SUMMARY'!C:D,2,0),) -> KS-881047 | C20: 46297 | E20: 1400
A21: TR356061 | B21: =IFERROR(VLOOKUP(A21,'Tổng,SUMMARY'!C:D,2,0),) -> KS-871270 | C21: 46297 | E21: 1200
A22: TR354809 | B22: =IFERROR(VLOOKUP(A22,'Tổng,SUMMARY'!C:D,2,0),) -> KS-880748 | C22: 46300 | E22: 2000
A23: TR355366 | B23: =IFERROR(VLOOKUP(A23,'Tổng,SUMMARY'!C:D,2,0),) -> KS-89046 | C23: 46300 | E23: 3960
... A119: TR356519 | B119: =IFERROR(VLOOKUP(A119,'Tổng,SUMMARY'!C:D,2,0),) -> KS-881490 | C119: 46312 | E119: 500
A120: TR356955 | B120: KS-881478 | C120: 46312 | E120: 400
A121: TR355682 | B121: =IFERROR(VLOOKUP(A121,'Tổng,SUMMARY'!C:D,2,0),) -> KS-881258(LP) | C121: 46312 | E121: 8000
A122: TR351649 | B122: KS-880104 | C122: 46312 | E122: 2200
A123: TR354395 | B123: KS-880760 | C123: 46312 | E123: 2500
A124: TR354759 | B124: =IFERROR(VLOOKUP(A124,'Tổng,SUMMARY'!C:D,2,0),) -> KS-880910 | C124: 46312 | E124: 15000
A125: TR352902 | B125: =IFERROR(VLOOKUP(A125,'Tổng,SUMMARY'!C:D,2,0),) -> KS-880442 | C125: 46314 | E125: 1000
A126: TR355713 | B126: =IFERROR(VLOOKUP(A126,'Tổng,SUMMARY'!C:D,2,0),) -> KS-870270 | C126: 46314 | E126: 900
A127: TR356463 | B127: =IFERROR(VLOOKUP(A127,'Tổng,SUMMARY'!C:D,2,0),) -> KS-890209 | C127: 46314 | E127: 960
A128: TR356716 | B128: =IFERROR(VLOOKUP(A128,'Tổng,SUMMARY'!C:D,2,0),) -> KS-880975 | C128: 46314 | E128: 400
A129: TR354466 | B129: =IFERROR(VLOOKUP(A129,'Tổng,SUMMARY'!C:D,2,0),) -> KS-89082 | C129: 46314 | E129: 210
A130: TR350031 | B130: =IFERROR(VLOOKUP(A130,'Tổng,SUMMARY'!C:D,2,0),) -> KS-8605 | C130: 46314 | E130: 5000
A131: TR300652 | B131: =IFERROR(VLOOKUP(A131,'Tổng,SUMMARY'!C:D,2,0),) -> KS-86015 | C131: 46314 | E131: 4000
A132: TR354224 | B132: =IFERROR(VLOOKUP(A132,'Tổng,SUMMARY'!C:D,2,0),) -> KS-880731 | C132: 46314 | E132: 10000
A133: TR351690 | B133: =IFERROR(VLOOKUP(A133,'Tổng,SUMMARY'!C:D,2,0),) -> KS-880272 | C133: 46314 | E133: 5800
A134: TR300155 | B134: =IFERROR(VLOOKUP(A134,'Tổng,SUMMARY'!C:D,2,0),) -> KS-8503 | C134: 46314 | E134: 3000
A135: TR352788 | B135: =IFERROR(VLOOKUP(A135,'Tổng,SUMMARY'!C:D,2,0),) -> KS-870247 | C135: 46314 | E135: 1000
... A144: TR354011 | B144: =IFERROR(VLOOKUP(A144,'Tổng,SUMMARY'!C:D,2,0),) -> KS-880624 | C144: 46315 | E144: 5000
B145: =IFERROR(VLOOKUP(A145,'Tổng,SUMMARY'!C:D,2,0),) -> 0
...

Sheet Tổng,SUMMARY
B1: TỔNG HỢP KHO THÀNH PHẨM THÁNG 10/2026 2026년/ 10월 완제품 현황
B2: 46316
B3: Item | C3: 전산코드 Mã ERP | D3: 모델명 Model | E3: 주요 출하 고객/ Khách hàng | F3: 온도 Nhiệt độ | G3: 박스단위 Quy cách ĐG | H3: Rev No. | I3: 사용장비 Máy | J3: 전월 재고 TỒN ĐẦU KỲ 30.09 | K3: 입고 Nhập | L3: 출고 XUẤT | Q3: 양품 재고 FG WH | S3: tồn thực tế tháng trk
L4: Xuất bán (Sales) | M4: Wait shipment | N4: Xuất Nội bộ (QA,nghiền) | O4: Xuất Mẫu (Sample)
B5: TRAY | C5: TR300011 | D5: KS-8205 | F5: 125140 | G5: M(50) | H5: Rev06 | J5: 0 | K5: =+SUMIF('Nhập kho 입'!A:A,C5,'Nhập kho 입'!E:E) -> 0 | L5: =+SUMIF(' Xuất kho 출'!A:A,C5,' Xuất kho 출'!E:E) -> 0 | O5: 0 | Q5: =+J5+K5-L5-N5 -> 0 | T5: =+R5-Q5 -> 0
B6: TRAY | C6: TR351822 | D6: KS-8212 | E6: ATP | F6: K/150 | G6: M(50) | H6: Rev03 | J6: 900 | K6: =+SUMIF('Nhập kho 입'!A:A,C6,'Nhập kho 입'!E:E) -> 0 | L6: =+SUMIF(' Xuất kho 출'!A:A,C6,' Xuất kho 출'!E:E) -> 0 | O6: 0 | Q6: =+J6+K6-L6-N6 -> 900 | R6: =18*50 -> 900 | T6: =+R6-Q6 -> 0
B7: TRAY | C7: TR352561 | D7: KS-8303 | E7: ASEM | F7: K/140 | G7: M(50) | H7: Rev03 | I7: 200Ton | J7: 0 | K7: =+SUMIF('Nhập kho 입'!A:A,C7,'Nhập kho 입'!E:E) -> 11750 | L7: =+SUMIF(' Xuất kho 출'!A:A,C7,' Xuất kho 출'!E:E) -> 0 | O7: 0 | Q7: =+J7+K7-L7-N7 -> 11750 | T7: =+R7-Q7 -> -11750
B8: TRAY | C8: TR300016 | D8: KS-8303 | E8: AMKOR-PH | F8: K/140 | G8: M(50) | H8: Rev03 | J8: 0 | K8: =+SUMIF('Nhập kho 입'!A:A,C8,'Nhập kho 입'!E:E) -> 0 | L8: =+SUMIF(' Xuất kho 출'!A:A,C8,' Xuất kho 출'!E:E) -> 0 | O8: 0 | Q8: =+J8+K8-L8-N8 -> 0 | T8: =+R8-Q8 -> 0
B9: TRAY | C9: TR300673 | D9: KS-8304 | E9: AMKOR-JP | F9: 120150 | G9: M(50) | H9: Rev04 | J9: 400 | K9: =+SUMIF('Nhập kho 입'!A:A,C9,'Nhập kho 입'!E:E) -> 0 | L9: =+SUMIF(' Xuất kho 출'!A:A,C9,' Xuất kho 출'!E:E) -> 0 | O9: 0 | Q9: =+J9+K9-L9-N9 -> 400 | R9: =8*50 -> 400 | T9: =+R9-Q9 -> 0
B10: TRAY | C10: TR351379 | D10: KS-8307 | E10: AMKOR-PH | G10: M(50) | H10: Rev03 | J10: 1550 | K10: =+SUMIF('Nhập kho 입'!A:A,C10,'Nhập kho 입'!E:E) -> 0 | L10: =+SUMIF(' Xuất kho 출'!A:A,C10,' Xuất kho 출'!E:E) -> 0 | O10: 0 | Q10: =+J10+K10-L10-N10 -> 1550 | R10: =200+350+19*50 -> 1500 | T10: =+R10-Q10 -> -50
B11: TRAY | C11: TR300108 | D11: KS-8308 | E11: CARSEM | F11: K/150 | G11: M(50) | H11: Rev01 | J11: 600 | K11: =+SUMIF('Nhập kho 입'!A:A,C11,'Nhập kho 입'!E:E) -> 0 | L11: =+SUMIF(' Xuất kho 출'!A:A,C11,' Xuất kho 출'!E:E) -> 0 | O11: 0 | Q11: =+J11+K11-L11-N11 -> 600 | R11: =4*50+8*50 -> 600 | T11: =+R11-Q11 -> 0
B12: TRAY | C12: TR350607 | D12: KS-84018 | E12: MMY | F12: K/125 | G12: M(100) | H12: Rev.K | J12: 1100 | K12: =+SUMIF('Nhập kho 입'!A:A,C12,'Nhập kho 입'!E:E) -> 0 | L12: =+SUMIF(' Xuất kho 출'!A:A,C12,' Xuất kho 출'!E:E) -> 0 | O12: 0 | Q12: =+J12+K12-L12-N12 -> 1100 | R12: 1100 | T12: =+R12-Q12 -> 0
B13: TRAY | C13: TR351941 | D13: KS-85012 | E13: TOMOE-T | F13: K/140 | G13: M(100) | H13: Rev00 | J13: 4700 | K13: =+SUMIF('Nhập kho 입'!A:A,C13,'Nhập kho 입'!E:E) -> 0 | L13: =+SUMIF(' Xuất kho 출'!A:A,C13,' Xuất kho 출'!E:E) -> 4000 | O13: 0 | Q13: =+J13+K13-L13-N13 -> 700 | R13: =200+3500 -> 3700 | T13: =+R13-Q13 -> 3000
B14: TRAY | C14: TR300155 | D14: KS-8503 | E14: XVIEW | F14: K/150 | G14: M(50) | H14: Rev04 | J14: 0 | K14: =+SUMIF('Nhập kho 입'!A:A,C14,'Nhập kho 입'!E:E) -> 8400 | L14: =+SUMIF(' Xuất kho 출'!A:A,C14,' Xuất kho 출'!E:E) -> 3000 | O14: 0 | Q14: =+J14+K14-L14-N14 -> 5400 | T14: =+R14-Q14 -> -5400
B15: TRAY | C15: TR300652 | D15: KS-86015 | E15: AMKOR-PH | F15: K/150 | G15: M(50) | H15: Rev00 | J15: 2400 | K15: =+SUMIF('Nhập kho 입'!A:A,C15,'Nhập kho 입'!E:E) -> 3600 | L15: =+SUMIF(' Xuất kho 출'!A:A,C15,' Xuất kho 출'!E:E) -> 4000 | O15: 0 | Q15: =+J15+K15-L15-N15 -> 2000 | R15: =39*50+9*50 -> 2400 | T15: =+R15-Q15 -> 400
B16: TRAY | C16: TR357102 | D16: KS-86015 | E16: ATEC | G16: M(50) | H16: Rev00 | J16: 0 | K16: =+SUMIF('Nhập kho 입'!A:A,C16,'Nhập kho 입'!E:E) -> 0 | L16: =+SUMIF(' Xuất kho 출'!A:A,C16,' Xuất kho 출'!E:E) -> 0 | O16: 0 | Q16: =+J16+K16-L16-N16 -> 0 | T16: =+R16-Q16 -> 0
B17: TRAY | C17: TR351120 | D17: KS-86015 | G17: M(50) | H17: Rev00 | J17: 200 | K17: =+SUMIF('Nhập kho 입'!A:A,C17,'Nhập kho 입'!E:E) -> 0 | L17: =+SUMIF(' Xuất kho 출'!A:A,C17,' Xuất kho 출'!E:E) -> 0 | O17: 0 | Q17: =+J17+K17-L17-N17 -> 200 | R17: 200 | T17: =+R17-Q17 -> 0
B18: TRAY | C18: TR352805 | D18: KS-86025 | E18: Tomoe-TH | F18: 125150 | G18: M(50) | H18: Rev00 | I18: 300Ton | J18: 1500 | K18: =+SUMIF('Nhập kho 입'!A:A,C18,'Nhập kho 입'!E:E) -> 0 | L18: =+SUMIF(' Xuất kho 출'!A:A,C18,' Xuất kho 출'!E:E) -> 0 | O18: 0 | Q18: =+J18+K18-L18-N18 -> 1500 | R18: =30*50 -> 1500 | T18: =+R18-Q18 -> 0
B19: TRAY | C19: TR353639 | D19: KS-86028 | E19: ATJ | F19: K/150 | G19: M(50) | H19: Rev00 | J19: 4950 | K19: =+SUMIF('Nhập kho 입'!A:A,C19,'Nhập kho 입'!E:E) -> 0 | L19: =+SUMIF(' Xuất kho 출'!A:A,C19,' Xuất kho 출'!E:E) -> 0 | O19: 0 | Q19: =+J19+K19-L19-N19 -> 4950 | R19: =73*50+24*50+100 -> 4950 | T19: =+R19-Q19 -> 0
B20: TRAY | C20: TR351141 | D20: KS-8603 | F20: 120/150 | G20: M(50) | H20: Rev04 | J20: 3450 | K20: =+SUMIF('Nhập kho 입'!A:A,C20,'Nhập kho 입'!E:E) -> 0 | L20: =+SUMIF(' Xuất kho 출'!A:A,C20,' Xuất kho 출'!E:E) -> 0 | O20: 0 | Q20: =+J20+K20-L20-N20 -> 3450 | R20: =69*50 -> 3450 | T20: =+R20-Q20 -> 0
B21: TRAY | C21: TR352974 | D21: KS-8605 | E21: DHL MY(INTEL) | F21: K/140 | G21: M(50) | H21: Rev00 | I21: 200Ton | J21: 750 | K21: =+SUMIF('Nhập kho 입'!A:A,C21,'Nhập kho 입'!E:E) -> 2850 | L21: =+SUMIF(' Xuất kho 출'!A:A,C21,' Xuất kho 출'!E:E) -> 0 | O21: 0 | Q21: =+J21+K21-L21-N21 -> 3600 | R21: =15*50 -> 750 | T21: =+R21-Q21 -> -2850
B22: TRAY | C22: TR350031 | D22: KS-8605 | E22: Amkor PH | F22: K/140 | G22: M(50) | H22: Rev00 | J22: 1750 | K22: =+SUMIF('Nhập kho 입'!A:A,C22,'Nhập kho 입'!E:E) -> 3600 | L22: =+SUMIF(' Xuất kho 출'!A:A,C22,' Xuất kho 출'!E:E) -> 5000 | O22: 0 | Q22: =+J22+K22-L22-N22 -> 350 | R22: =35*50 -> 1750 | T22: =+R22-Q22 -> 1400
B23: TRAY | C23: TR352031 | D23: KS-870161 | E23: ASE-TW | F23: K/150 | G23: S(50) | H23: Rev01 | J23: 2600 | K23: =+SUMIF('Nhập kho 입'!A:A,C23,'Nhập kho 입'!E:E) -> 700 | L23: =+SUMIF(' Xuất kho 출'!A:A,C23,' Xuất kho 출'!E:E) -> 0 | O23: 0 | Q23: =+J23+K23-L23-N23 -> 3300 | R23: =41*50+11*50 -> 2600 | T23: =+R23-Q23 -> -700
B24: TRAY | C24: TR350605 | D24: KS-870161 | E24: ASE PH | F24: K/150 | G24: S(50) | H24: Rev00 | J24: 1100 | K24: =+SUMIF('Nhập kho 입'!A:A,C24,'Nhập kho 입'!E:E) -> 0 | L24: =+SUMIF(' Xuất kho 출'!A:A,C24,' Xuất kho 출'!E:E) -> 0 | O24: 0 | Q24: =+J24+K24-L24-N24 -> 1100 | R24: =19*50+150 -> 1100 | T24: =+R24-Q24 -> 0
B25: TRAY | C25: TR351434 | D25: KS-870163 | E25: UTAC-TH | F25: K/150 | G25: S(50) | H25: Rev00 | J25: 600 | K25: =+SUMIF('Nhập kho 입'!A:A,C25,'Nhập kho 입'!E:E) -> 0 | L25: =+SUMIF(' Xuất kho 출'!A:A,C25,' Xuất kho 출'!E:E) -> 0 | O25: 0 | Q25: =+J25+K25-L25-N25 -> 600 | R25: =5*50+350 -> 600 | T25: =+R25-Q25 -> 0
B26: TRAY | C26: TR351274 | D26: KS-870163 | F26: K/140 | G26: S(50) | H26: Rev00 | J26: 750 | K26: =+SUMIF('Nhập kho 입'!A:A,C26,'Nhập kho 입'!E:E) -> 0 | L26: =+SUMIF(' Xuất kho 출'!A:A,C26,' Xuất kho 출'!E:E) -> 0 | O26: 0 | Q26: =+J26+K26-L26-N26 -> 750 | R26: =8*50+350 -> 750 | T26: =+R26-Q26 -> 0
B27: TRAY | C27: TR355770 | D27: KS-870197 | E27: ASE-TW | G27: S(50) | H27: Rev00 | J27: 2900 | K27: =+SUMIF('Nhập kho 입'!A:A,C27,'Nhập kho 입'!E:E) -> 0 | L27: =+SUMIF(' Xuất kho 출'!A:A,C27,' Xuất kho 출'!E:E) -> 1500 | O27: 0 | Q27: =+J27+K27-L27-N27 -> 1400 | R27: =56*50 -> 2800 | T27: =+R27-Q27 -> 1400
B28: TRAY | C28: TR354006 | D28: KS-870208 | E28: Tong Hsing | F28: K/140 | G28: M(100) | H28: Rev00 | J28: 100 | K28: =+SUMIF('Nhập kho 입'!A:A,C28,'Nhập kho 입'!E:E) -> 0 | L28: =+SUMIF(' Xuất kho 출'!A:A,C28,' Xuất kho 출'!E:E) -> 0 | O28: 0 | Q28: =+J28+K28-L28-N28 -> 100 | R28: 100 | T28: =+R28-Q28 -> 0
B29: TRAY | C29: TR351743 | D29: KS-870217 | E29: ADI-MY | F29: K/150 | G29: M(50) | H29: Rev00 | J29: 1250 | K29: =+SUMIF('Nhập kho 입'!A:A,C29,'Nhập kho 입'!E:E) -> 0 | L29: =+SUMIF(' Xuất kho 출'!A:A,C29,' Xuất kho 출'!E:E) -> 0 | O29: 0 | Q29: =+J29+K29-L29-N29 -> 1250 | R29: =25*50 -> 1250 | T29: =+R29-Q29 -> 0
B30: TRAY | C30: TR351886 | D30: KS-870217 | E30: Anstek | G30: M(50) | H30: Rev00 | J30: 0 | K30: =+SUMIF('Nhập kho 입'!A:A,C30,'Nhập kho 입'!E:E) -> 0 | L30: =+SUMIF(' Xuất kho 출'!A:A,C30,' Xuất kho 출'!E:E) -> 0 | O30: 0 | Q30: =+J30+K30-L30-N30 -> 0 | T30: =+R30-Q30 -> 0
B31: TRAY | C31: TR356704 | D31: KS-881608 | E31: SPIL BUYER | F31: K/140 | G31: M(50) | H31: Rev00 | J31: 0 | K31: =+SUMIF('Nhập kho 입'!A:A,C31,'Nhập kho 입'!E:E) -> 500 | L31: =+SUMIF(' Xuất kho 출'!A:A,C31,' Xuất kho 출'!E:E) -> 200 | O31: 0 | Q31: =+J31+K31-L31-N31 -> 300 | T31: =+R31-Q31 -> -300
B32: TRAY | C32: TR355714 | D32: KS-870234 | E32: ADI-MY | G32: M(50) | H32: Rev00 | J32: 5600 | K32: =+SUMIF('Nhập kho 입'!A:A,C32,'Nhập kho 입'!E:E) -> 0 | L32: =+SUMIF(' Xuất kho 출'!A:A,C32,' Xuất kho 출'!E:E) -> 0 | O32: 0 | Q32: =+J32+K32-L32-N32 -> 5600 | R32: =19*50+17*50+8*50+68*50 -> 5600 | T32: =+R32-Q32 -> 0
B33: TRAY | C33: TR353784 | D33: KS-870247 | E33: ASE TEST | F33: K/150 | G33: S(50) | H33: Rev00 | J33: 300 | K33: =+SUMIF('Nhập kho 입'!A:A,C33,'Nhập kho 입'!E:E) -> 5200 | L33: =+SUMIF(' Xuất kho 출'!A:A,C33,' Xuất kho 출'!E:E) -> 3800 | O33: 0 | Q33: =+J33+K33-L33-N33 -> 1700 | R33: =6*50 -> 300 | T33: =+R33-Q33 -> -1400
B34: TRAY | C34: TR352788 | D34: KS-870247 | E34: TOMOE-T | F34: K/150 | G34: S(50) | H34: Rev00 | J34: 50 | K34: =+SUMIF('Nhập kho 입'!A:A,C34,'Nhập kho 입'!E:E) -> 3350 | L34: =+SUMIF(' Xuất kho 출'!A:A,C34,' Xuất kho 출'!E:E) -> 1000 | O34: 0 | Q34: =+J34+K34-L34-N34 -> 2400 | R34: 50 | T34: =+R34-Q34 -> -2350
B35: TRAY | C35: TR356413 | D35: KS-881478 | E35: ASE-TW | G35: M(50) | J35: 0 | K35: =+SUMIF('Nhập kho 입'!A:A,C35,'Nhập kho 입'!E:E) -> 1700 | L35: =+SUMIF(' Xuất kho 출'!A:A,C35,' Xuất kho 출'!E:E) -> 400 | O35: 0 | Q35: =+J35+K35-L35-N35 -> 1300 | R35: 50 | T35: =+R35-Q35 -> -1250
B36: TRAY | C36: TR351902 | D36: KS-870252 | E36: VALLEN | G36: S(50) | H36: Rev00 | J36: 1050 | K36: =+SUMIF('Nhập kho 입'!A:A,C36,'Nhập kho 입'!E:E) -> 0 | L36: =+SUMIF(' Xuất kho 출'!A:A,C36,' Xuất kho 출'!E:E) -> 0 | O36: 0 | Q36: =+J36+K36-L36-N36 -> 1050 | R36: =21*50 -> 1050 | T36: =+R36-Q36 -> 0
B37: TRAY | C37: TR354314 | D37: KS-870252 | E37: ASE TEST | G37: S(50) | H37: Rev00 | J37: 0 | K37: =+SUMIF('Nhập kho 입'!A:A,C37,'Nhập kho 입'!E:E) -> 1000 | L37: =+SUMIF(' Xuất kho 출'!A:A,C37,' Xuất kho 출'!E:E) -> 0 | Q37: =+J37+K37-L37-N37 -> 1000
B38: TRAY | C38: TR352461 | D38: KS-870252 | E38: AMKOR CN | G38: S(50) | H38: Rev00 | J38: 500 | K38: =+SUMIF('Nhập kho 입'!A:A,C38,'Nhập kho 입'!E:E) -> 0 | L38: =+SUMIF(' Xuất kho 출'!A:A,C38,' Xuất kho 출'!E:E) -> 0 | O38: 0 | Q38: =+J38+K38-L38-N38 -> 500 | R38: 500 | T38: =+R38-Q38 -> 0
B39: TRAY | C39: TR351833 | D39: KS-870253 | E39: ADI-MY | G39: M(50) | H39: Rev00 | J39: 1750 | K39: =+SUMIF('Nhập kho 입'!A:A,C39,'Nhập kho 입'!E:E) -> 0 | L39: =+SUMIF(' Xuất kho 출'!A:A,C39,' Xuất kho 출'!E:E) -> 500 | O39: 0 | Q39: =+J39+K39-L39-N39 -> 1250 | R39: =200+35*50 -> 1950 | T39: =+R39-Q39 -> 700
B40: TRAY | C40: TR354280 | D40: KS-870264 | E40: UTAC-TH | F40: K/150 | G40: S(50) | H40: Rev00 | J40: 1650 | K40: =+SUMIF('Nhập kho 입'!A:A,C40,'Nhập kho 입'!E:E) -> 0 | L40: =+SUMIF(' Xuất kho 출'!A:A,C40,' Xuất kho 출'!E:E) -> 0 | O40: 0 | Q40: =+J40+K40-L40-N40 -> 1650 | R40: =33*50 -> 1650 | T40: =+R40-Q40 -> 0
...

Sheet Lot
A1: Code | B1: Tên | C1: Lot | D1: Số Lượng | E1: Tồn kho
A2: TR354564 | B2: KS-880822
C3: TV20260823011 | D3: 100
C4: TV20260823010 | D4: 100
C5: TV20261013006 | D5: 100
C6: TV20261013005 | D6: 1200
C9: TV20261010017 | D9: 1200
C10: TV20261010035 | D10: 500
C11: TV20261010016 | D11: 1200
C12: TV20261010036 | D12: 1200
A16: Tổng | D16: =SUM(D2:D15) -> 5600 | E16: =+VLOOKUP(A2,'Tổng,SUMMARY'!C:Q,15,0) -> 5600
A17: TR351743 | B17: KS-870217 | C17: tồn c | D17: 250
C18: TV20260729014 | D18: 1000
A24: Tổng | D24: =SUM(D17:D23) -> 1250 | E24: =+VLOOKUP(A17,'Tổng,SUMMARY'!C:Q,15,0) -> 1250
A25: TR355604 | B25: KS-881163
C26: TV20260821007 | D26: 1100
C27: TV20260822018 | D27: 1200
C28: TV20260826008 | D28: 1200
C29: TV20260826009 | D29: 1200
C30: TV20260831006 | D30: 1200
C31: TV20260825009 | D31: 1200
C32: TV20260827006 | D32: 1200
C33: TV20260829013 | D33: 1000
C34: TV20260827007 | D34: 1200
C35: TV20260821008 | D35: 1200
C36: TV20260828006 | D36: 500
A41: Tổng | D41: =SUM(D25:D40) -> 12200 | E41: =+'Tổng,SUMMARY'!$Q$206 -> 12200
A42: TR355940 | B42: KS-881169 | C42: TỒN CŨ | D42: 200
C45: TV20260829015 | D45: 1200
C46: TV20260831008 | D46: 1200
C47: TV20260827008 | D47: 1200
C48: TV20260828007 | D48: 300
C49: TV20260903012 | D49: 1200
C56: TV20260831025 | D56: 700
C57: TV20260820006 | D57: 1200
C58: TV20260831026 | D58: 1000
C59: TV20260829014 | D59: 1200
A66: Tổng | D66: =SUM(D42:D65) -> 9400 | E66: =+'Tổng,SUMMARY'!$Q$208 -> 9400 | F66: =+E66-D66 -> 0
A67: Code | B67: Tên | C67: Lot | D67: Số Lượng
A68: TR354691 | B68: KS-880887 | C68: TỒN CŨ | D68: 1900
...

Sheet gia công
D1: 10
A2: Stt | B2: Code | C2: Tên | D2: TT | E2: =DATE(2026,$D$1,1)-1 -> 46295 | F2: =DATE(2026,$D$1,1) -> 46296 | G2: =+F2+1 -> 46297 | H2: =+G2+1 -> 46298 | I2: =+H2+1 -> 46299 | J2: =+I2+1 -> 46300 | K2: =+J2+1 -> 46301 | L2: =+K2+1 -> 46302 | M2: =+L2+1 -> 46303 | N2: =+M2+1 -> 46304 | ... AL2: =+AK2+1 -> 46328
A3: 1 | B3: TR355708 | C3: KS-880827 | D3: =SUM(F3:AL3) -> 0 | AM3: =SUMIF('Nhập kho 입'!A:A,'gia công'!B:B,'Nhập kho 입'!E:E) -> 0 | AN3: =+D3-AM3 -> 0
A4: 2 | B4: TR352327 | C4: KS-880372 | D4: =SUM(F4:AL4) -> 30650 | H4: 2400 | J4: =2400+2400 -> 4800 | L4: 2400 | M4: 2400 | N4: =2400+2400 -> 4800 | Q4: 2400 | R4: 1850 | U4: 2400 | V4: 2400 | X4: 2400 | Y4: 2400 | AM4: =SUMIF('Nhập kho 입'!A:A,'gia công'!B:B,'Nhập kho 입'!E:E) -> 30650 | AN4: =+D4-AM4 -> 0
A5: 3 | B5: TR354914 | C5: KS-880959 | D5: =SUM(F5:AL5) -> 14550 | E5: 7200 | F5: =2400+2400 -> 4800 | K5: 150 | X5: 2400 | Y5: 2400 | Z5: =2400+2400 -> 4800 | AM5: =SUMIF('Nhập kho 입'!A:A,'gia công'!B:B,'Nhập kho 입'!E:E) -> 14550 | AN5: =+D5-AM5 -> 0
A6: 4 | B6: TR354952 | C6: KS-880944 | D6: =SUM(F6:AL6) -> 50400 | E6: 7200 | F6: 3600 | G6: 3600 | J6: 3600 | K6: 3600 | M6: 3600 | N6: 3600 | Q6: 3600 | R6: 3600 | T6: 7200 | U6: 3600 | X6: 3600 | Y6: 3600 | Z6: 3600 | AM6: =SUMIF('Nhập kho 입'!A:A,'gia công'!B:B,'Nhập kho 입'!E:E) -> 74100 | AN6: =+D6-AM6 -> -23700
A7: 5 | B7: TR300652 | C7: KS-86015 | D7: =SUM(F7:AL7) -> 3600 | R7: 3600 | X7: 3600 | Z7: -3600 | AM7: =SUMIF('Nhập kho 입'!A:A,'gia công'!B:B,'Nhập kho 입'!E:E) -> 3600 | AN7: =+D7-AM7 -> 0
A8: 6 | B8: TR357102 | C8: KS-86015 | D8: =SUM(F8:AL8) -> 0 | AM8: =SUMIF('Nhập kho 입'!A:A,'gia công'!B:B,'Nhập kho 입'!E:E) -> 0 | AN8: =+D8-AM8 -> 0
A9: 7 | B9: TR351120 | C9: KS-86015 | D9: =SUM(F9:AL9) -> 0 | AM9: =SUMIF('Nhập kho 입'!A:A,'gia công'!B:B,'Nhập kho 입'!E:E) -> 0 | AN9: =+D9-AM9 -> 0
A10: 8 | B10: TR355136 | C10: KS-881041 | D10: =SUM(F10:AL10) -> 0 | AM10: =SUMIF('Nhập kho 입'!A:A,'gia công'!B:B,'Nhập kho 입'!E:E) -> 16750 | AN10: =+D10-AM10-AO10 -> -16750
A11: 9 | B11: TR354288 | C11: KS-880753 | D11: =SUM(F11:AL11) -> 26550 | E11: 7200 | F11: 3600 | G11: 3600 | K11: =3600+3600 -> 7200 | L11: 3600 | N11: 3600 | R11: 3600 | U11: 1350 | AM11: =SUMIF('Nhập kho 입'!A:A,'gia công'!B:B,'Nhập kho 입'!E:E) -> 26550 | AN11: =+D11-AM11 -> 0
A12: 10 | B12: TR356497 | C12: KS-881512 | D12: =SUM(F12:AL12) -> 21600 | E12: 7200 | F12: 3600 | N12: 3600 | S12: =3600+3600 -> 7200 | V12: 3600 | X12: 3600 | AM12: =SUMIF('Nhập kho 입'!A:A,'gia công'!B:B,'Nhập kho 입'!E:E) -> 21600 | AN12: =+D12-AM12 -> 0
A13: 11 | B13: TR355669 | C13: KS-871056 | D13: =SUM(F13:AL13) -> 0 | AM13: =SUMIF('Nhập kho 입'!A:A,'gia công'!B:B,'Nhập kho 입'!E:E) -> 7850 | AN13: =+D13-AM13 -> -7850
A14: 12 | B14: TR351690 | C14: KS-880272 | D14: =SUM(F14:AL14) -> 0 | AM14: =SUMIF('Nhập kho 입'!A:A,'gia công'!B:B,'Nhập kho 입'!E:E) -> 0 | AN14: =+D14-AM14 -> 0
A15: 13 | B15: TR355235 | C15: KS-870849 | D15: =SUM(F15:AL15) -> 0 | AM15: =SUMIF('Nhập kho 입'!A:A,'gia công'!B:B,'Nhập kho 입'!E:E) -> 0 | AN15: =+D15-AM15 -> 0
A16: 14 | B16: TR300155 | C16: KS-8503 | D16: =SUM(F16:AL16) -> 8400 | H16: 3600 | K16: 3600 | M16: 1200 | AM16: =SUMIF('Nhập kho 입'!A:A,'gia công'!B:B,'Nhập kho 입'!E:E) -> 8400 | AN16: =+D16-AM16 -> 0
A17: 15 | B17: TR356623 | C17: KS-881576 | D17: =SUM(F17:AL17) -> 0 | AM17: =SUMIF('Nhập kho 입'!A:A,'gia công'!B:B,'Nhập kho 입'!E:E) -> 0 | AN17: =+D17-AM17 -> 0
A18: 16 | B18: TR352561 | C18: KS-8303 | D18: =SUM(F18:AL18) -> 11750 | G18: 3600 | H18: 3600 | M18: 3300 | V18: 1250 | AM18: =SUMIF('Nhập kho 입'!A:A,'gia công'!B:B,'Nhập kho 입'!E:E) -> 11750 | AN18: =+D18-AM18 -> 0
A19: 17 | B19: TR300016 | C19: KS-8303 | D19: =SUM(F19:AL19) -> 0 | AM19: =SUMIF('Nhập kho 입'!A:A,'gia công'!B:B,'Nhập kho 입'!E:E) -> 0 | AN19: =+D19-AM19 -> 0
A20: 18 | B20: TR352974 | C20: KS-8605 | D20: =SUM(F20:AL20) -> 2850 | Q20: 2850 | AM20: =SUMIF('Nhập kho 입'!A:A,'gia công'!B:B,'Nhập kho 입'!E:E) -> 2850 | AN20: =+D20-AM20 -> 0
A21: 19 | B21: TR350031 | C21: KS-8605 | D21: =SUM(F21:AL21) -> 3600 | F21: 3600 | G21: -3600 | K21: 3600 | AM21: =SUMIF('Nhập kho 입'!A:A,'gia công'!B:B,'Nhập kho 입'!E:E) -> 3600 | AN21: =+D21-AM21 -> 0
A22: 20 | B22: TR354821 | C22: KS-89069 | D22: =SUM(F22:AL22) -> 0 | AM22: =SUMIF('Nhập kho 입'!A:A,'gia công'!B:B,'Nhập kho 입'!E:E) -> 0 | AN22: =+D22-AM22 -> 0
A23: 21 | B23: TR355134 | C23: KS-89069 | D23: =SUM(F23:AL23) -> 17280 | K23: 2160 | L23: 2160 | N23: 2160 | Q23: 2160 | T23: 2160 | U23: =2160+2160 -> 4320 | V23: 2160 | AM23: =SUMIF('Nhập kho 입'!A:A,'gia công'!B:B,'Nhập kho 입'!E:E) -> 17280 | AN23: =+D23-AM23 -> 0
B24: TR353784 | C24: KS-870247 | D24: =SUM(F24:AL24) -> 0 | AM24: =SUMIF('Nhập kho 입'!A:A,'gia công'!B:B,'Nhập kho 입'!E:E) -> 5200 | AN24: =+D24-AM24 -> -5200
A25: 22 | B25: TR352788 | C25: KS-870247 | D25: =SUM(F25:AL25) -> 0 | AM25: =SUMIF('Nhập kho 입'!A:A,'gia công'!B:B,'Nhập kho 입'!E:E) -> 3350 | AN25: =+D25-AM25 -> -3350
A26: 23 | B26: TR356297 | C26: KS-871365 | D26: =SUM(F26:AL26) -> 0 | AM26: =SUMIF('Nhập kho 입'!A:A,'gia công'!B:B,'Nhập kho 입'!E:E) -> 0 | AN26: =+D26-AM26 -> 0
A27: 24 | B27: TR351313 | C27: KS-87049 | D27: =SUM(F27:AL27) -> 0 | AM27: =SUMIF('Nhập kho 입'!A:A,'gia công'!B:B,'Nhập kho 입'!E:E) -> 0 | AN27: =+D27-AM27 -> 0
A28: 25 | B28: TR351317 | C28: KS-87049 | D28: =SUM(F28:AL28) -> 2050 | L28: 2050 | AM28: =SUMIF('Nhập kho 입'!A:A,'gia công'!B:B,'Nhập kho 입'!E:E) -> 2050 | AN28: =+D28-AM28 -> 0
A29: 26 | B29: TR356580 | C29: KS-881515 | D29: =SUM(F29:AL29) -> 0 | AM29: =SUMIF('Nhập kho 입'!A:A,'gia công'!B:B,'Nhập kho 입'!E:E) -> 0 | AN29: =+D29-AM29 -> 0
A30: 27 | B30: TR355276 | C30: KS-881080 | D30: =SUM(F30:AL30) -> 9050 | Q30: 2000 | R30: =2000+2000 -> 4000 | U30: 2000 | X30: 1050 | AM30: =SUMIF('Nhập kho 입'!A:A,'gia công'!B:B,'Nhập kho 입'!E:E) -> 9050 | AN30: =+D30-AM30 -> 0
A31: 28 | B31: TR351434 | C31: KS-870163 | D31: =SUM(F31:AL31) -> 0 | AM31: =SUMIF('Nhập kho 입'!A:A,'gia công'!B:B,'Nhập kho 입'!E:E) -> 0 | AN31: =+D31-AM31 -> 0
A32: 29 | B32: TR355918 | C32: KS-881300 | D32: =SUM(F32:AL32) -> 15000 | L32: 1000 | Q32: 2000 | R32: 2000 | S32: 2000 | U32: =2000+2000 -> 4000 | X32: =2000+2000 -> 4000 | AM32: =SUMIF('Nhập kho 입'!A:A,'gia công'!B:B,'Nhập kho 입'!E:E) -> 23450 | AN32: =+D32-AM32+AO32 -> -8450
A33: 30 | B33: TR353125 | C33: KS-8809 | D33: =SUM(F33:AL33) -> 0 | AM33: =SUMIF('Nhập kho 입'!A:A,'gia công'!B:B,'Nhập kho 입'!E:E) -> 7850 | AN33: =+D33-AM33+AO33 -> -7850
A34: 31 | B34: TR354279 | C34: KS-880373 | D34: =SUM(F34:AL34) -> 0 | AM34: =SUMIF('Nhập kho 입'!A:A,'gia công'!B:B,'Nhập kho 입'!E:E) -> 0 | AN34: =+D34-AM34 -> 0
C35: =+D35+E35 -> 246130 | D35: =SUM(D3:D34) -> 217330 | E35: =SUM(E3:E34) -> 28800 | F35: =SUM(F3:F34) -> 19200 | G35: =SUM(G3:G34) -> 7200 | H35: =SUM(H3:H34) -> 9600 | I35: =SUM(I3:I34) -> 0 | J35: =SUM(J3:J34) -> 8400 | K35: =SUM(K3:K34) -> 20310 | ... AL35: =SUM(AL3:AL34) -> 0 | AM35: =SUM(AM3:AM34)-AM10-AM32-AM33 -> 242430 | AN35: =SUM(AN3:AN34)-AN10 -> -56400 | AO35: =SUM(AO3:AO34)-AO10 -> 0
A37: Stt | B37: Xuất NVL Đóng gói T08 | C37: Tên | D37: TT | E37: =DATE(2026,$D$1,1) -> 46296 | F37: =+E37+1 -> 46297 | G37: =+F37+1 -> 46298 | H37: =+G37+1 -> 46299 | I37: =+H37+1 -> 46300 | J37: =+I37+1 -> 46301 | K37: =+J37+1 -> 46302 | L37: =+K37+1 -> 46303 | M37: =+L37+1 -> 46304 | ... AL37: =+AK37+1 -> 46329
A38: 1 | C38: M50 /1001 | D38: =SUM(E38:AL38) -> 1250 | E38: 500 | J38: 750
A39: 2 | C39: S50 /1002 | D39: =SUM(E39:AL39) -> 1690 | K39: 700 | P39: 510 | S39: 480
A40: 3 | C40: Tấm lót thùng | D40: =SUM(E40:AL40) -> 0
A41: 4 | C41: Nắp pallet | D41: =SUM(E41:AL41) -> 0
...
